Workbook

Sheet リーグ勝敗表
E4: 1 | H4: 2 | K4: 3 | N4: 4 | Q4: 5 | T4: 6 | W4: 7 | Z4: 8 | AC4: 9 | AF4: 10 | AI4: 11
B5: チーム名 | E5: =C6 | H5: =C8 | K5: =C10 | N5: =C12 | Q5: =C14 | T5: =C16 | W5: =C18 | Z5: =C20 | AC5: =C22 | AF5: =C24 | AI5: =C26 | AL5: 勝 | AM5: 分 | AN5: 敗 | AO5: 勝点 | AP5: 失点 | AQ5: 得点 | AR5: 残試 | AS5: 順位 | AW5: チームナンバー | AZ5: チームリスト
B6: 1 | C6: =AX6 | H6: =IF(H7="","",IF(H7="☂","☂",IF(H7>J7,"○",IF(H7=J7,"△","×")))) | K6: =IF(K7="","",IF(K7="☂","☂",IF(K7>M7,"○",IF(K7=M7,"△","×")))) | N6: =IF(N7="","",IF(N7="☂","☂",IF(N7>P7,"○",IF(N7=P7,"△","×")))) | Q6: =IF(Q7="","",IF(Q7="☂","☂",IF(Q7>S7,"○",IF(Q7=S7,"△","×")))) | T6: =IF(T7="","",IF(T7="☂","☂",IF(T7>V7,"○",IF(T7=V7,"△","×")))) | W6: =IF(W7="","",IF(W7="☂","☂",IF(W7>Y7,"○",IF(W7=Y7,"△","×")))) | Z6: =IF(Z7="","",IF(Z7="☂","☂",IF(Z7>AB7,"○",IF(Z7=AB7,"△","×")))) | AC6: =IF(AC7="","",IF(AC7="☂","☂",IF(AC7>AE7,"○",IF(AC7=AE7,"△","×")))) | AF6: =IF(AF7="","",IF(AF7="☂","☂",IF(AF7>AH7,"○",IF(AF7=AH7,"△","×")))) | AI6: =IF(AI7="","",IF(AI7="☂","☂",IF(AI7>AK7,"○",IF(AI7=AK7,"△","×")))) | AL6: =COUNTIF(E6:AK6,"○") | AM6: =COUNTIF(E6:AK6,"△") | AN6: =COUNTIF(E6:AK6,"×") | AO6: =AL6*3+AM6*1 | AP6: =SUM(J7,M7,P7,S7,V7,Y7,AB7,AK7) | AQ6: =SUM(H7,K7,N7,Q7,T7,W7,Z7,AI7) | AR6: =$AY$21-AL6-AM6-AN6 | AS6: =IFERROR(_xlfn.RANK.EQ(AO6,$AO$6:$AO$27),"") | AV6: 1 | AW6: 1 | AX6: =IFERROR(VLOOKUP(AW6,AZ$6:BA$20,2,0),"") | AZ6: 1 | BA6: 野宮塗装
H7: =IF(G9="","",G9) | I7: - | J7: =IF(E9="","",E9) | K7: =IF(G11="","",G11) | L7: - | M7: =IF(E11="","",E11) | N7: =IF(G13="","",G13) | O7: - | P7: =IF(E13="","",E13) | Q7: =IF(G15="","",G15) | R7: - | S7: =IF(E15="","",E15) | T7: =IF(G17="","",G17) | U7: - | V7: =IF(E17="","",E17) | W7: =IF(G19="","",G19) | X7: - | Y7: =IF(E19="","",E19) | Z7: =IF(G21="","",G21) | AA7: - | AB7: =IF(E21="","",E21) | AC7: =IF(G23="","",G23) | AD7: - | AE7: =IF(E23="","",E23) | AF7: =IF(G25="","",G25) | AG7: - | AH7: =IF(E25="","",E25) | AI7: =IF(G27="","",G27) | AJ7: - | AK7: =IF(E27="","",G27) | AZ7: 2 | BA7: 飯詰
B8: 2 | C8: =AX8 | E8: =IF(E9="","",IF(E9="☂","☂",IF(E9>G9,"○",IF(E9=G9,"△","×")))) | K8: =IF(K9="","",IF(K9="☂","☂",IF(K9>M9,"○",IF(K9=M9,"△","×")))) | N8: =IF(N9="","",IF(N9="☂","☂",IF(N9>P9,"○",IF(N9=P9,"△","×")))) | Q8: =IF(Q9="","",IF(Q9="☂","☂",IF(Q9>S9,"○",IF(Q9=S9,"△","×")))) | T8: =IF(T9="","",IF(T9="☂","☂",IF(T9>V9,"○",IF(T9=V9,"△","×")))) | W8: =IF(W9="","",IF(W9="☂","☂",IF(W9>Y9,"○",IF(W9=Y9,"△","×")))) | Z8: =IF(Z9="","",IF(Z9="☂","☂",IF(Z9>AB9,"○",IF(Z9=AB9,"△","×")))) | AC8: =IF(AC9="","",IF(AC9="☂","☂",IF(AC9>AE9,"○",IF(AC9=AE9,"△","×")))) | AF8: =IF(AF9="","",IF(AF9="☂","☂",IF(AF9>AH9,"○",IF(AF9=AH9,"△","×")))) | AI8: =IF(AI9="","",IF(AI9="☂","☂",IF(AI9>AK9,"○",IF(AI9=AK9,"△","×")))) | AL8: =COUNTIF(E8:AK8,"○") | AM8: =COUNTIF(E8:AK8,"△") | AN8: =COUNTIF(E8:AK8,"×") | AO8: =AL8*3+AM8*1 | AP8: =SUM(G9,M9,P9,S9,V9,Y9,AB9,AK9) | AQ8: =SUM(E9,K9,N9,Q9,T9,W9,Z9,AI9) | AR8: =$AY$21-AL8-AM8-AN8 | AS8: =IFERROR(_xlfn.RANK.EQ(AO8,$AO$6:$AO$27),"") | AV8: 2 | AW8: 2 | AX8: =IFERROR(VLOOKUP(AW8,AZ$6:BA$20,2,0),"") | AZ8: 3 | BA8: バッカス
F9: - | K9: =IF(J11="","",J11) | L9: - | M9: =IF(H11="","",H11) | N9: =IF(J13="","",J13) | O9: - | P9: =IF(H13="","",H13) | Q9: =IF(J15="","",J15) | R9: - | S9: =IF(H15="","",H15) | T9: =IF(J17="","",J17) | U9: - | V9: =IF(H17="","",H17) | W9: =IF(J19="","",J19) | X9: - | Y9: =IF(H19="","",H19) | Z9: =IF(J21="","",J21) | AA9: - | AB9: =IF(H21="","",H21) | AC9: =IF(J23="","",J23) | AD9: - | AE9: =IF(H23="","",H23) | AF9: =IF(J25="","",J25) | AG9: - | AH9: =IF(H25="","",H25) | AI9: =IF(J27="","",J27) | AJ9: - | AK9: =IF(H27="","",H27) | AZ9: 4 | BA9: ウエスタン
B10: 3 | C10: =AX10 | E10: =IF(E11="","",IF(E11="☂","☂",IF(E11>G11,"○",IF(E11=G11,"△","×")))) | H10: =IF(H11="","",IF(H11="☂","☂",IF(H11>J11,"○",IF(H11=J11,"△","×")))) | N10: =IF(N11="","",IF(N11="☂","☂",IF(N11>P11,"○",IF(N11=P11,"△","×")))) | Q10: =IF(Q11="","",IF(Q11="☂","☂",IF(Q11>S11,"○",IF(Q11=S11,"△","×")))) | T10: =IF(T11="","",IF(T11="☂","☂",IF(T11>V11,"○",IF(T11=V11,"△","×")))) | W10: =IF(W11="","",IF(W11="☂","☂",IF(W11>Y11,"○",IF(W11=Y11,"△","×")))) | Z10: =IF(Z11="","",IF(Z11="☂","☂",IF(Z11>AB11,"○",IF(Z11=AB11,"△","×")))) | AC10: =IF(AC11="","",IF(AC11="☂","☂",IF(AC11>AE11,"○",IF(AC11=AE11,"△","×")))) | AF10: =IF(AF11="","",IF(AF11="☂","☂",IF(AF11>AH11,"○",IF(AF11=AH11,"△","×")))) | AI10: =IF(AI11="","",IF(AI11="☂","☂",IF(AI11>AK11,"○",IF(AI11=AK11,"△","×")))) | AL10: =COUNTIF(E10:AK10,"○") | AM10: =COUNTIF(E10:AK10,"△") | AN10: =COUNTIF(E10:AK10,"×") | AO10: =AL10*3+AM10*1 | AP10: =SUM(G11,J11,M11,P11,S11,V11,Y11,AB11,AK11) | AQ10: =SUM(E11,H11,K11,N11,Q11,T11,W11,Z11,AI11) | AR10: =$AY$21-AL10-AM10-AN10 | AS10: =IFERROR(_xlfn.RANK.EQ(AO10,$AO$6:$AO$27),"") | AV10: 3 | AW10: 3 | AX10: =IFERROR(VLOOKUP(AW10,AZ$6:BA$20,2,0),"") | AZ10: 5 | BA10: 富士電機
I11: - | N11: =IF(M13="","",M13) | O11: - | P11: =IF(K13="","",K13) | Q11: =IF(M15="","",M15) | R11: - | S11: =IF(K15="","",K15) | T11: =IF(M17="","",M17) | U11: - | V11: =IF(K17="","",K17) | W11: =IF(M19="","",M19) | X11: - | Y11: =IF(K19="","",K19) | Z11: =IF(M21="","",M21) | AA11: - | AB11: =IF(K21="","",K21) | AC11: =IF(M23="","",M23) | AD11: - | AE11: =IF(K23="","",K23) | AF11: =IF(M25="","",M25) | AG11: - | AH11: =IF(K25="","",K25) | AI11: =IF(M27="","",M27) | AJ11: - | AK11: =IF(K27="","",K27) | AZ11: 6 | BA11: 日産
B12: 4 | C12: =AX12 | E12: =IF(E13="","",IF(E13="☂","☂",IF(E13>G13,"○",IF(E13=G13,"△","×")))) | H12: =IF(H13="","",IF(H13="☂","☂",IF(H13>J13,"○",IF(H13=J13,"△","×")))) | K12: =IF(K13="","",IF(K13="☂","☂",IF(K13>M13,"○",IF(K13=M13,"△","×")))) | Q12: =IF(Q13="","",IF(Q13="☂","☂",IF(Q13>S13,"○",IF(Q13=S13,"△","×")))) | T12: =IF(T13="","",IF(T13="☂","☂",IF(T13>V13,"○",IF(T13=V13,"△","×")))) | W12: =IF(W13="","",IF(W13="☂","☂",IF(W13>Y13,"○",IF(W13=Y13,"△","×")))) | Z12: =IF(Z13="","",IF(Z13="☂","☂",IF(Z13>AB13,"○",IF(Z13=AB13,"△","×")))) | AC12: =IF(AC13="","",IF(AC13="☂","☂",IF(AC13>AE13,"○",IF(AC13=AE13,"△","×")))) | AF12: =IF(AF13="","",IF(AF13="☂","☂",IF(AF13>AH13,"○",IF(AF13=AH13,"△","×")))) | AI12: =IF(AI13="","",IF(AI13="☂","☂",IF(AI13>AK13,"○",IF(AI13=AK13,"△","×")))) | AL12: =COUNTIF(E12:AK12,"○") | AM12: =COUNTIF(E12:AK12,"△") | AN12: =COUNTIF(E12:AK12,"×") | AO12: =AL12*3+AM12*1 | AP12: =SUM(G13,J13,M13,P13,S13,V13,Y13,AB13,AK13) | AQ12: =SUM(E13,H13,K13,N13,Q13,T13,W13,Z13,AI13) | AR12: =$AY$21-AL12-AM12-AN12 | AS12: =IFERROR(_xlfn.RANK.EQ(AO12,$AO$6:$AO$27),"") | AV12: 4 | AW12: 4 | AX12: =IFERROR(VLOOKUP(AW12,AZ$6:BA$20,2,0),"") | AZ12: 7
F13: - | I13: - | L13: - | Q13: =IF(P15="","",P15) | R13: - | S13: =IF(N15="","",N15) | T13: =IF(P17="","",P17) | U13: - | V13: =IF(N17="","",N17) | W13: =IF(P19="","",P19) | X13: - | Y13: =IF(N19="","",N19) | Z13: =IF(P21="","",P21) | AA13: - | AB13: =IF(N21="","",N21) | AC13: =IF(P23="","",P23) | AD13: - | AE13: =IF(N23="","",N23) | AF13: =IF(P25="","",P25) | AG13: - | AH13: =IF(N25="","",N25) | AI13: =IF(P27="","",P27) | AJ13: - | AK13: =IF(N27="","",N27) | AZ13: 8
B14: 5 | C14: =AX14 | E14: =IF(E15="","",IF(E15="☂","☂",IF(E15>G15,"○",IF(E15=G15,"△","×")))) | H14: =IF(H15="","",IF(H15="☂","☂",IF(H15>J15,"○",IF(H15=J15,"△","×")))) | K14: =IF(K15="","",IF(K15="☂","☂",IF(K15>M15,"○",IF(K15=M15,"△","×")))) | N14: =IF(N15="","",IF(N15="☂","☂",IF(N15>P15,"○",IF(N15=P15,"△","×")))) | T14: =IF(T15="","",IF(T15="☂","☂",IF(T15>V15,"○",IF(T15=V15,"△","×")))) | W14: =IF(W15="","",IF(W15="☂","☂",IF(W15>Y15,"○",IF(W15=Y15,"△","×")))) | Z14: =IF(Z15="","",IF(Z15="☂","☂",IF(Z15>AB15,"○",IF(Z15=AB15,"△","×")))) | AC14: =IF(AC15="","",IF(AC15="☂","☂",IF(AC15>AE15,"○",IF(AC15=AE15,"△","×")))) | AF14: =IF(AF15="","",IF(AF15="☂","☂",IF(AF15>AH15,"○",IF(AF15=AH15,"△","×")))) | AI14: =IF(AI15="","",IF(AI15="☂","☂",IF(AI15>AK15,"○",IF(AI15=AK15,"△","×")))) | AL14: =COUNTIF(E14:AK14,"○") | AM14: =COUNTIF(E14:AK14,"△") | AN14: =COUNTIF(E14:AK14,"×") | AO14: =AL14*3+AM14*1 | AP14: =SUM(G15,J15,M15,P15,S15,V15,Y15,AB15,AK15) | AQ14: =SUM(E15,H15,K15,N15,Q15,T15,W15,Z15,AI15) | AR14: =$AY$21-AL14-AM14-AN14 | AS14: =IFERROR(_xlfn.RANK.EQ(AO14,$AO$6:$AO$27),"") | AV14: 5 | AW14: 5 | AX14: =IFERROR(VLOOKUP(AW14,AZ$6:BA$20,2,0),"") | AZ14: 9
F15: - | I15: - | L15: - | O15: - | T15: =IF(S17="","",S17) | U15: - | V15: =IF(Q17="","",Q17) | W15: =IF(S19="","",S19) | X15: - | Y15: =IF(Q19="","",Q19) | Z15: =IF(S21="","",S21) | AA15: - | AB15: =IF(Q21="","",Q21) | AC15: =IF(S23="","",S23) | AD15: - | AE15: =IF(Q31="","",Q31) | AF15: =IF(S25="","",S25) | AG15: - | AH15: =IF(Q25="","",Q25) | AI15: =IF(S27="","",S27) | AJ15: - | AK15: =IF(Q27="","",Q27) | AZ15: 10
B16: 6 | C16: =AX16 | E16: =IF(E17="","",IF(E17="☂","☂",IF(E17>G17,"○",IF(E17=G17,"△","×")))) | H16: =IF(H17="","",IF(H17="☂","☂",IF(H17>J17,"○",IF(H17=J17,"△","×")))) | K16: =IF(K17="","",IF(K17="☂","☂",IF(K17>M17,"○",IF(K17=M17,"△","×")))) | N16: =IF(N17="","",IF(N17="☂","☂",IF(N17>P17,"○",IF(N17=P17,"△","×")))) | Q16: =IF(Q17="","",IF(Q17="☂","☂",IF(Q17>S17,"○",IF(Q17=S17,"△","×")))) | W16: =IF(W17="","",IF(W17="☂","☂",IF(W17>Y17,"○",IF(W17=Y17,"△","×")))) | Z16: =IF(Z17="","",IF(Z17="☂","☂",IF(Z17>AB17,"○",IF(Z17=AB17,"△","×")))) | AC16: =IF(AC17="","",IF(AC17="☂","☂",IF(AC17>AE17,"○",IF(AC17=AE17,"△","×")))) | AF16: =IF(AF17="","",IF(AF17="☂","☂",IF(AF17>AH17,"○",IF(AF17=AH17,"△","×")))) | AI16: =IF(AI17="","",IF(AI17="☂","☂",IF(AI17>AK17,"○",IF(AI17=AK17,"△","×")))) | AL16: =COUNTIF(E16:AK16,"○") | AM16: =COUNTIF(E16:AK16,"△") | AN16: =COUNTIF(E16:AK16,"×") | AO16: =AL16*3+AM16*1 | AP16: =SUM(G17,J17,M17,P17,S17,V17,Y17,AB17,AK17) | AQ16: =SUM(E17,H17,K17,N17,Q17,T17,W17,Z17,AI17) | AR16: =$AY$21-AL16-AM16-AN16 | AS16: =IFERROR(_xlfn.RANK.EQ(AO16,$AO$6:$AO$27),"") | AV16: 6 | AW16: 6 | AX16: =IFERROR(VLOOKUP(AW16,AZ$6:BA$20,2,0),"") | AZ16: 11
F17: - | I17: - | L17: - | O17: - | R17: - | W17: =IF(V19="","",V19) | X17: - | Y17: =IF(T19="","",T19) | Z17: =IF(V21="","",V21) | AA17: - | AB17: =IF(T21="","",T21) | AC17: =IF(V23="","",V23) | AD17: - | AE17: =IF(T23="","",T23) | AF17: =IF(V25="","",V25) | AG17: - | AH17: =IF(T25="","",T25) | AI17: =IF(V27="","",V27) | AJ17: - | AK17: =IF(T27="","",T27) | AZ17: 12
B18: 7 | C18: =AX18 | E18: =IF(E19="","",IF(E19="☂","☂",IF(E19>G19,"○",IF(E19=G19,"△","×")))) | H18: =IF(H19="","",IF(H19="☂","☂",IF(H19>J19,"○",IF(H19=J19,"△","×")))) | K18: =IF(K19="","",IF(K19="☂","☂",IF(K19>M19,"○",IF(K19=M19,"△","×")))) | N18: =IF(N19="","",IF(N19="☂","☂",IF(N19>P19,"○",IF(N19=P19,"△","×")))) | Q18: =IF(Q19="","",IF(Q19="☂","☂",IF(Q19>S19,"○",IF(Q19=S19,"△","×")))) | T18: =IF(T19="","",IF(T19="☂","☂",IF(T19>V19,"○",IF(T19=V19,"△","×")))) | Z18: =IF(Z19="","",IF(Z19="☂","☂",IF(Z19>AB19,"○",IF(Z19=AB19,"△","×")))) | AC18: =IF(AC19="","",IF(AC19="☂","☂",IF(AC19>AE19,"○",IF(AC19=AE19,"△","×")))) | AF18: =IF(AF19="","",IF(AF19="☂","☂",IF(AF19>AH19,"○",IF(AF19=AH19,"△","×")))) | AI18: =IF(AI19="","",IF(AI19="☂","☂",IF(AI19>AK19,"○",IF(AI19=AK19,"△","×")))) | AL18: =COUNTIF(E18:AK18,"○") | AM18: =COUNTIF(E18:AK18,"△") | AN18: =COUNTIF(E18:AK18,"×") | AO18: =AL18*3+AM18*1 | AP18: =SUM(G19,J19,M19,P19,S19,V19,Y19,AB19,AK19) | AQ18: =SUM(E19,H19,K19,N19,Q19,T19,W19,Z19,AI19) | AR18: =$AY$21-AL18-AM18-AN18 | AS18: =IFERROR(_xlfn.RANK.EQ(AO18,$AO$6:$AO$27),"") | AV18: 7 | AX18: =IFERROR(VLOOKUP(AW18,AZ$6:BA$20,2,0),"") | AZ18: 13
F19: - | I19: - | L19: - | O19: - | R19: - | U19: - | Z19: =IF(Y21="","",Y21) | AA19: - | AB19: =IF(W21="","",W21) | AC19: =IF(Y23="","",Y23) | AD19: - | AE19: =IF(W23="","",W23) | AF19: =IF(Y25="","",Y25) | AG19: - | AH19: =IF(W25="","",W25) | AI19: =IF(Y27="","",Y27) | AJ19: - | AK19: =IF(W27="","",W27) | AZ19: 14
B20: 8 | C20: =AX20 | E20: =IF(E21="","",IF(E21="☂","☂",IF(E21>G21,"○",IF(E21=G21,"△","×")))) | H20: =IF(H21="","",IF(H21="☂","☂",IF(H21>J21,"○",IF(H21=J21,"△","×")))) | K20: =IF(K21="","",IF(K21="☂","☂",IF(K21>M21,"○",IF(K21=M21,"△","×")))) | N20: =IF(N21="","",IF(N21="☂","☂",IF(N21>P21,"○",IF(N21=P21,"△","×")))) | Q20: =IF(Q21="","",IF(Q21="☂","☂",IF(Q21>S21,"○",IF(Q21=S21,"△","×")))) | T20: =IF(T21="","",IF(T21="☂","☂",IF(T21>V21,"○",IF(T21=V21,"△","×")))) | W20: =IF(W21="","",IF(W21="☂","☂",IF(W21>Y21,"○",IF(W21=Y21,"△","×")))) | AC20: =IF(AC21="","",IF(AC21="☂","☂",IF(AC21>AE21,"○",IF(AC21=AE21,"△","×")))) | AF20: =IF(AF21="","",IF(AF21="☂","☂",IF(AF21>AH21,"○",IF(AF21=AH21,"△","×")))) | AI20: =IF(AI21="","",IF(AI21="☂","☂",IF(AI21>AK21,"○",IF(AI21=AK21,"△","×")))) | AL20: =COUNTIF(E20:AK20,"○") | AM20: =COUNTIF(E20:AK20,"△") | AN20: =COUNTIF(E20:AK20,"×") | AO20: =AL20*3+AM20*1 | AP20: =SUM(G21,J21,M21,P21,S21,V21,Y21,AB21,AK21) | AQ20: =SUM(E21,H21,K21,N21,Q21,T21,W21,Z21,AI21) | AR20: =$AY$21-AL20-AM20-AN20 | AS20: =IFERROR(_xlfn.RANK.EQ(AO20,$AO$6:$AO$27),"") | AV20: 8 | AX20: =IFERROR(VLOOKUP(AW20,AZ$6:BA$20,2,0),"") | AZ20: 15
F21: - | I21: - | L21: - | O21: - | R21: - | U21: - | X21: - | AC21: =IF(AB23="","",AB23) | AD21: - | AE21: =IF(Z23="","",Z23) | AF21: =IF(AB25="","",AB25) | AG21: - | AH21: =IF(Z25="","",Z25) | AI21: =IF(AB27="","",AB27) | AJ21: - | AK21: =IF(Z27="","",Z27) | AY21: =COUNTA(AW6:AW21)
B22: 9 | C22: =AX22 | E22: =IF(E23="","",IF(E23="☂","☂",IF(E23>G23,"○",IF(E23=G23,"△","×")))) | H22: =IF(H23="","",IF(H23="☂","☂",IF(H23>J23,"○",IF(H23=J23,"△","×")))) | K22: =IF(K23="","",IF(K23="☂","☂",IF(K23>M23,"○",IF(K23=M23,"△","×")))) | N22: =IF(N23="","",IF(N23="☂","☂",IF(N23>P23,"○",IF(N23=P23,"△","×")))) | Q22: =IF(Q23="","",IF(Q23="☂","☂",IF(Q23>S23,"○",IF(Q23=S23,"△","×")))) | T22: =IF(T23="","",IF(T23="☂","☂",IF(T23>V23,"○",IF(T23=V23,"△","×")))) | W22: =IF(W23="","",IF(W23="☂","☂",IF(W23>Y23,"○",IF(W23=Y23,"△","×")))) | Z22: =IF(Z23="","",IF(Z23="☂","☂",IF(Z23>AB23,"○",IF(Z23=AB23,"△","×")))) | AF22: =IF(AF23="","",IF(AF23="☂","☂",IF(AF23>AH23,"○",IF(AF23=AH23,"△","×")))) | AI22: =IF(AI23="","",IF(AI23="☂","☂",IF(AI23>AK23,"○",IF(AI23=AK23,"△","×")))) | AL22: =COUNTIF(E22:AK22,"○") | AM22: =COUNTIF(E22:AK22,"△") | AN22: =COUNTIF(E22:AK22,"×") | AO22: =AL22*3+AM22*1 | AP22: =SUM(G23,M23,P23,S23,V23,Y23,AB23,AK23) | AQ22: =SUM(E23,K23,N23,Q23,T23,W23,Z23,AI23) | AR22: =10-AL22-AM22-AN22 | AS22: =IFERROR(_xlfn.RANK.EQ(AO22,$AO$6:$AO$27),"") | AV22: 9 | AX22: =IFERROR(VLOOKUP(AW22,AZ$6:BA$20,2,0),"")
F23: - | I23: - | L23: - | O23: - | R23: - | U23: - | X23: - | AA23: - | AF23: =IF(AE25="","",AE25) | AG23: - | AH23: =IF(AC25="","",AC25) | AI23: =IF(AE27="","",AE27) | AJ23: - | AK23: =IF(AC27="","",AC27)
B24: 10 | C24: =AX24 | E24: =IF(E25="","",IF(E25="☂","☂",IF(E25>G25,"○",IF(E25=G25,"△","×")))) | H24: =IF(H25="","",IF(H25="☂","☂",IF(H25>J25,"○",IF(H25=J25,"△","×")))) | K24: =IF(K25="","",IF(K25="☂","☂",IF(K25>M25,"○",IF(K25=M25,"△","×")))) | N24: =IF(N25="","",IF(N25="☂","☂",IF(N25>P25,"○",IF(N25=P25,"△","×")))) | Q24: =IF(Q25="","",IF(Q25="☂","☂",IF(Q25>S25,"○",IF(Q25=S25,"△","×")))) | T24: =IF(T25="","",IF(T25="☂","☂",IF(T25>V25,"○",IF(T25=V25,"△","×")))) | W24: =IF(W25="","",IF(W25="☂","☂",IF(W25>Y25,"○",IF(W25=Y25,"△","×")))) | Z24: =IF(Z25="","",IF(Z25="☂","☂",IF(Z25>AB25,"○",IF(Z25=AB25,"△","×")))) | AC24: =IF(AC25="","",IF(AC25="☂","☂",IF(AC25>AE25,"○",IF(AC25=AE25,"△","×")))) | AI24: =IF(AI25="","",IF(AI25="☂","☂",IF(AI25>AK25,"○",IF(AI25=AK25,"△","×")))) | AL24: =COUNTIF(E24:AK24,"○") | AM24: =COUNTIF(E24:AK24,"△") | AN24: =COUNTIF(E24:AK24,"×") | AO24: =AL24*3+AM24*1 | AP24: =SUM(G25,M25,P25,S25,V25,Y25,AB25,AK25) | AQ24: =SUM(E25,K25,N25,Q25,T25,W25,Z25,AI25) | AR24: =10-AL24-AM24-AN24 | AS24: =IFERROR(_xlfn.RANK.EQ(AO24,$AO$6:$AO$27),"") | AV24: 10 | AX24: =IFERROR(VLOOKUP(AW24,AZ$6:BA$20,2,0),"")
F25: - | I25: - | L25: - | O25: - | R25: - | U25: - | X25: - | AA25: - | AD25: - | AI25: =IF(AH27="","",AH27) | AJ25: - | AK25: =IF(AF27="","",AF27)
B26: 11 | C26: =AX26 | E26: =IF(E27="","",IF(E27="☂","☂",IF(E27>G27,"○",IF(E27=G27,"△","×")))) | H26: =IF(H27="","",IF(H27="☂","☂",IF(H27>J27,"○",IF(H27=J27,"△","×")))) | K26: =IF(K27="","",IF(K27="☂","☂",IF(K27>M27,"○",IF(K27=M27,"△","×")))) | N26: =IF(N27="","",IF(N27="☂","☂",IF(N27>P27,"○",IF(N27=P27,"△","×")))) | Q26: =IF(Q27="","",IF(Q27="☂","☂",IF(Q27>S27,"○",IF(Q27=S27,"△","×")))) | T26: =IF(T27="","",IF(T27="☂","☂",IF(T27>V27,"○",IF(T27=V27,"△","×")))) | W26: =IF(W27="","",IF(W27="☂","☂",IF(W27>Y27,"○",IF(W27=Y27,"△","×")))) | Z26: =IF(Z27="","",IF(Z27="☂","☂",IF(Z27>AB27,"○",IF(Z27=AB27,"△","×")))) | AC26: =IF(AC27="","",IF(AC27="☂","☂",IF(AC27>AE27,"○",IF(AC27=AE27,"△","×")))) | AF26: =IF(AF27="","",IF(AF27="☂","☂",IF(AF27>AH27,"○",IF(AF27=AH27,"△","×")))) | AL26: =COUNTIF(E26:AK26,"○") | AM26: =COUNTIF(E26:AK26,"△") | AN26: =COUNTIF(E26:AK26,"×") | AO26: =AL26*3+AM26*1 | AP26: =SUM(G27,M27,P27,S27,V27,Y27,AB27,AK27) | AQ26: =SUM(H27,K27,N27,Q27,T27,W27,Z27,AI27,#REF!) | AR26: =10-AL26-AM26-AN26 | AS26: =IFERROR(_xlfn.RANK.EQ(AO26,$AO$6:$AO$27),"") | AV26: 11 | AX26: =IFERROR(VLOOKUP(AW26,AZ$6:BA$20,2,0),"")
F27: - | I27: - | L27: - | O27: - | R27: - | U27: - | X27: - | AA27: - | AD27: - | AG27: -

Sheet 日程表１
A1: R8朝野球日程表 | T1: 2026 | W1: 年
A2: 5月 | G2: 6月 | M2: 7月 | S2: 8月
A3: 日 | B3: 曜日 | C3: 対戦チーム | F3: 審判 | G3: 日 | H3: 曜日 | I3: 対戦チーム | L3: 審判 | M3: 日 | N3: 曜日 | O3: 対戦チーム | R3: 審判 | S3: 日 | T3: 曜日 | U3: 対戦チーム | X3: 審判
A4: 45047 | B4: 金 | D4: ー | G4: 45078 | H4: 月 | J4: ー | M4: 45108 | N4: 水 | O4: =IFERROR(VLOOKUP(3,リーグ勝敗表!$AZ$6:$BA$11,2,0),"3") | P4: ー | Q4: =IFERROR(VLOOKUP(4,リーグ勝敗表!$AZ$6:$BA$11,2,0),"4") | R4: =IFERROR(VLOOKUP(1,リーグ勝敗表!$AZ$6:$BA$11,2,0),"1")&"-"&IFERROR(VLOOKUP(5,リーグ勝敗表!$AZ$6:$BA$11,2,0),"5") | S4: 45139 | T4: 土 | V4: ー
A5: 45048 | B5: 土 | D5: ー | G5: 45079 | H5: 火 | I5: =IFERROR(VLOOKUP(1,リーグ勝敗表!$AZ$6:$BA$11,2,0),"1") | J5: ー | K5: =IFERROR(VLOOKUP(6,リーグ勝敗表!$AZ$6:$BA$11,2,0),"6") | L5: =IFERROR(VLOOKUP(2,リーグ勝敗表!$AZ$6:$BA$11,2,0),"2")&"-"&IFERROR(VLOOKUP(4,リーグ勝敗表!$AZ$6:$BA$11,2,0),"4") | M5: 45109 | N5: 木 | O5: =IFERROR(VLOOKUP(2,リーグ勝敗表!$AZ$6:$BA$11,2,0),"2") | P5: ー | Q5: =IFERROR(VLOOKUP(6,リーグ勝敗表!$AZ$6:$BA$11,2,0),"6") | R5: =IFERROR(VLOOKUP(3,リーグ勝敗表!$AZ$6:$BA$11,2,0),"3")&"-"&IFERROR(VLOOKUP(4,リーグ勝敗表!$AZ$6:$BA$11,2,0),"4") | S5: 45140 | T5: 日 | V5: ー
A6: 45049 | B6: 日 | D6: ー | G6: 45080 | H6: 水 | I6: =IFERROR(VLOOKUP(2,リーグ勝敗表!$AZ$6:$BA$11,2,0),"2") | J6: ー | K6: =IFERROR(VLOOKUP(3,リーグ勝敗表!$AZ$6:$BA$11,2,0),"3") | L6: =IFERROR(VLOOKUP(1,リーグ勝敗表!$AZ$6:$BA$11,2,0),"1")&"-"&IFERROR(VLOOKUP(6,リーグ勝敗表!$AZ$6:$BA$11,2,0),"6") | M6: 45110 | N6: 金 | P6: ー | S6: 45141 | T6: 月 | V6: ー
A7: 45050 | B7: 月 | D7: ー | G7: 45081 | H7: 木 | I7: =IFERROR(VLOOKUP(4,リーグ勝敗表!$AZ$6:$BA$11,2,0),"4") | J7: ー | K7: =IFERROR(VLOOKUP(5,リーグ勝敗表!$AZ$6:$BA$11,2,0),"5") | L7: =IFERROR(VLOOKUP(2,リーグ勝敗表!$AZ$6:$BA$11,2,0),"2")&"-"&IFERROR(VLOOKUP(3,リーグ勝敗表!$AZ$6:$BA$11,2,0),"3") | M7: 45111 | N7: 土 | P7: ー | S7: 45142 | T7: 火 | V7: ー
A8: 45051 | B8: 火 | D8: ー | G8: 45082 | H8: 金 | J8: ー | M8: 45112 | N8: 日 | P8: ー | S8: 45143 | T8: 水 | V8: ー
A9: 45052 | B9: 水 | D9: ー | G9: 45083 | H9: 土 | J9: ー | M9: 45113 | N9: 月 | P9: ー | S9: 45144 | T9: 木 | V9: ー
A10: 45053 | B10: 木 | D10: ー | G10: 45084 | H10: 日 | J10: ー | M10: 45114 | N10: 火 | P10: ー | S10: 45145 | T10: 金 | V10: ー
A11: 45054 | B11: 金 | D11: ー | G11: 45085 | H11: 月 | J11: ー | M11: 45115 | N11: 水 | P11: ー | S11: 45146 | T11: 土 | V11: ー
A12: 45055 | B12: 土 | D12: ー | G12: 45086 | H12: 火 | I12: =IFERROR(VLOOKUP(1,リーグ勝敗表!$AZ$6:$BA$11,2,0),"1") | J12: ー | K12: =IFERROR(VLOOKUP(2,リーグ勝敗表!$AZ$6:$BA$11,2,0),"2") | L12: =IFERROR(VLOOKUP(4,リーグ勝敗表!$AZ$6:$BA$11,2,0),"4")&"-"&IFERROR(VLOOKUP(5,リーグ勝敗表!$AZ$6:$BA$11,2,0),"5") | M12: 45116 | N12: 木 | P12: ー | S12: 45147 | T12: 日 | V12: ー
A13: 45056 | B13: 日 | D13: ー | G13: 45087 | H13: 水 | I13: =IFERROR(VLOOKUP(3,リーグ勝敗表!$AZ$6:$BA$11,2,0),"3") | J13: ー | K13: =IFERROR(VLOOKUP(5,リーグ勝敗表!$AZ$6:$BA$11,2,0),"5") | L13: =IFERROR(VLOOKUP(1,リーグ勝敗表!$AZ$6:$BA$11,2,0),"1")&"-"&IFERROR(VLOOKUP(2,リーグ勝敗表!$AZ$6:$BA$11,2,0),"2") | M13: 45117 | N13: 金 | P13: ー | S13: 45148 | T13: 月 | V13: ー
A14: 45057 | B14: 月 | D14: ー | G14: 45088 | H14: 木 | I14: =IFERROR(VLOOKUP(4,リーグ勝敗表!$AZ$6:$BA$11,2,0),"4") | J14: ー | K14: =IFERROR(VLOOKUP(6,リーグ勝敗表!$AZ$6:$BA$11,2,0),"6") | L14: =IFERROR(VLOOKUP(3,リーグ勝敗表!$AZ$6:$BA$11,2,0),"3")&"-"&IFERROR(VLOOKUP(5,リーグ勝敗表!$AZ$6:$BA$11,2,0),"5") | M14: 45118 | N14: 土 | P14: ー | S14: 45149 | T14: 火 | V14: ー
A15: 45058 | B15: 火 | D15: ー | G15: 45089 | H15: 金 | J15: ー | M15: 45119 | N15: 日 | P15: ー | S15: 45150 | T15: 水 | V15: ー
A16: 45059 | B16: 水 | D16: ー | G16: 45090 | H16: 土 | J16: ー | M16: 45120 | N16: 月 | P16: ー | S16: 45151 | T16: 木 | V16: ー
A17: 45060 | B17: 木 | D17: ー | G17: 45091 | H17: 日 | J17: ー | M17: 45121 | N17: 火 | P17: ー | S17: 45152 | T17: 金 | V17: ー
A18: 45061 | B18: 金 | D18: ー | G18: 45092 | H18: 月 | J18: ー | M18: 45122 | N18: 水 | P18: ー | S18: 45153 | T18: 土 | V18: ー
A19: 45062 | B19: 土 | D19: ー | G19: 45093 | H19: 火 | I19: 予備日 | M19: 45123 | N19: 木 | P19: ー | S19: 45154 | T19: 日 | V19: ー
A20: 45063 | B20: 日 | D20: ー | G20: 45094 | H20: 水 | I20: 予備日 | M20: 45124 | N20: 金 | P20: ー | S20: 45155 | T20: 月 | V20: ー
A21: 45064 | B21: 月 | D21: ー | G21: 45095 | H21: 木 | I21: 予備日 | M21: 45125 | N21: 土 | P21: ー | S21: 45156 | T21: 火 | V21: ー
A22: 45065 | B22: 火 | D22: ー | G22: 45096 | H22: 金 | M22: 45126 | N22: 日 | P22: ー | T22: 水
A23: 45066 | B23: 水 | D23: ー | G23: 45097 | H23: 土 | M23: 45127 | N23: 月 | P23: ー | S23: NO. | T23: 木
A24: 45067 | B24: 木 | D24: ー | G24: 45098 | H24: 日 | M24: 45128 | N24: 火 | P24: ー | S24: 1 | T24: 金
A25: 45068 | B25: 金 | D25: ー | G25: 45099 | H25: 月 | M25: 45129 | N25: 水 | P25: ー | S25: 2 | T25: 土
A26: 45069 | B26: 土 | D26: ー | G26: 45100 | H26: 火 | I26: =IFERROR(VLOOKUP(2,リーグ勝敗表!$AZ$6:$BA$11,2,0),"2") | K26: =IFERROR(VLOOKUP(5,リーグ勝敗表!$AZ$6:$BA$11,2,0),"5") | L26: =IFERROR(VLOOKUP(4,リーグ勝敗表!$AZ$6:$BA$11,2,0),"4")&"-"&IFERROR(VLOOKUP(6,リーグ勝敗表!$AZ$6:$BA$11,2,0),"6") | M26: 45130 | N26: 木 | P26: ー | S26: 3 | T26: 日
A27: 45070 | B27: 日 | D27: ー | G27: 45101 | H27: 水 | I27: =IFERROR(VLOOKUP(1,リーグ勝敗表!$AZ$6:$BA$11,2,0),"1") | K27: =IFERROR(VLOOKUP(4,リーグ勝敗表!$AZ$6:$BA$11,2,0),"4") | L27: =IFERROR(VLOOKUP(2,リーグ勝敗表!$AZ$6:$BA$11,2,0),"2")&"-"&IFERROR(VLOOKUP(5,リーグ勝敗表!$AZ$6:$BA$11,2,0),"5") | M27: 45131 | N27: 金 | P27: ー | S27: 4 | T27: 月
A28: 45071 | B28: 月 | D28: ー | G28: 45102 | H28: 木 | I28: =IFERROR(VLOOKUP(3,リーグ勝敗表!$AZ$6:$BA$11,2,0),"3") | K28: =IFERROR(VLOOKUP(6,リーグ勝敗表!$AZ$6:$BA$11,2,0),"6") | L28: =IFERROR(VLOOKUP(1,リーグ勝敗表!$AZ$6:$BA$11,2,0),"1")&"-"&IFERROR(VLOOKUP(4,リーグ勝敗表!$AZ$6:$BA$11,2,0),"4") | M28: 45132 | N28: 土 | P28: ー | S28: 5 | T28: 火
A29: 45072 | B29: 火 | C29: =IFERROR(VLOOKUP(1,リーグ勝敗表!$AZ$6:$BA$11,2,0),"1") | D29: ー | E29: =IFERROR(VLOOKUP(3,リーグ勝敗表!$AZ$6:$BA$11,2,0),"3") | F29: =IFERROR(VLOOKUP(2,リーグ勝敗表!$AZ$6:$BA$11,2,0),"2")&"-"&IFERROR(VLOOKUP(6,リーグ勝敗表!$AZ$6:$BA$11,2,0),"6") | G29: 45103 | H29: 金 | M29: 45133 | N29: 日 | P29: ー | S29: 6 | T29: 水
A30: 45073 | B30: 水 | C30: =IFERROR(VLOOKUP(5,リーグ勝敗表!$AZ$6:$BA$11,2,0),"5") | D30: ー | E30: =IFERROR(VLOOKUP(6,リーグ勝敗表!$AZ$6:$BA$11,2,0),"6") | F30: =IFERROR(VLOOKUP(1,リーグ勝敗表!$AZ$6:$BA$11,2,0),"1")&"-"&IFERROR(VLOOKUP(3,リーグ勝敗表!$AZ$6:$BA$11,2,0),"3") | G30: 45104 | H30: 土 | M30: 45134 | N30: 月 | P30: ー | S30: 7 | T30: 木
A31: 45074 | B31: 木 | C31: =IFERROR(VLOOKUP(2,リーグ勝敗表!$AZ$6:$BA$11,2,0),"2") | D31: ー | E31: =IFERROR(VLOOKUP(4,リーグ勝敗表!$AZ$6:$BA$11,2,0),"4") | F31: =IFERROR(VLOOKUP(5,リーグ勝敗表!$AZ$6:$BA$11,2,0),"5")&"-"&IFERROR(VLOOKUP(6,リーグ勝敗表!$AZ$6:$BA$11,2,0),"6") | G31: 45105 | H31: 日 | M31: 45135 | N31: 火 | P31: ー | S31: 8 | T31: 金
A32: 45075 | B32: 金 | D32: ー | G32: 45106 | H32: 月 | M32: 45136 | N32: 水 | P32: ー | S32: 9 | T32: 土
A33: 45076 | B33: 土 | D33: ー | G33: 45107 | H33: 火 | I33: =IFERROR(VLOOKUP(1,リーグ勝敗表!$AZ$6:$BA$11,2,0),"1") | K33: =IFERROR(VLOOKUP(5,リーグ勝敗表!$AZ$6:$BA$11,2,0),"5") | L33: =IFERROR(VLOOKUP(3,リーグ勝敗表!$AZ$6:$BA$11,2,0),"3")&"-"&IFERROR(VLOOKUP(6,リーグ勝敗表!$AZ$6:$BA$11,2,0),"6") | M33: 45137 | N33: 木 | P33: ー | S33: 10 | T33: 日
A34: 45077 | B34: 日 | D34: ー | M34: 45138 | N34: 金 | P34: ー | T34: 月
A35: ◇ | B35: 審判は、投手板・打者席に「水」をまき整備し、ラインは紐を使い真っ直ぐに引く。
A36: ◇ | B36: 「たばこ」や「ゴミ」を捨てないように。ゴミは必ずチームで持ち帰ること。
B37: ※市営球場は施設内全面禁煙となります。
B39: メンバー表交換 ・・・・・ ５時10分 （提出できないチームは不戦敗）
B40: 試合時間 ・・・・・ ５時１５分～６時４５分
F41: ※ 6時40分を越えて新しいイニングには入らない
...

Sheet 使い方
A1: リーグ戦 勝敗表 使い方

Sheet 日程表２
A1: 朝野球日程表 | T1: =日程表１!T1 | W1: 年
A2: 5月 | G2: 6月 | M2: 7月 | S2: 8月
A3: 日 | B3: 曜日 | C3: 対戦チーム | F3: 審判 | G3: 日 | H3: 曜日 | I3: 対戦チーム | L3: 審判 | M3: 日 | N3: 曜日 | O3: 対戦チーム | R3: 審判 | S3: 日 | T3: 曜日 | U3: 対戦チーム | X3: 審判
A4: =日程表１!A4 | B4: =日程表１!B4 | D4: ー | G4: =日程表１!G4 | H4: =日程表１!H4 | J4: ー | M4: =日程表１!M4 | N4: =日程表１!N4 | O4: =IFERROR(VLOOKUP(3,リーグ勝敗表!$AZ$6:$BA$11,2,0),"3") | P4: ー | Q4: =IFERROR(VLOOKUP(4,リーグ勝敗表!$AZ$6:$BA$11,2,0),"4") | R4: =IFERROR(VLOOKUP(1,リーグ勝敗表!$AZ$6:$BA$11,2,0),"1")&"-"&IFERROR(VLOOKUP(5,リーグ勝敗表!$AZ$6:$BA$11,2,0),"5") | S4: =日程表１!S5 | T4: =日程表１!T5 | V4: ー
A5: =日程表１!A5 | B5: =日程表１!B5 | D5: ー | G5: =日程表１!G5 | H5: =日程表１!H5 | I5: =IFERROR(VLOOKUP(1,リーグ勝敗表!$AZ$6:$BA$11,2,0),"1") | J5: ー | K5: =IFERROR(VLOOKUP(6,リーグ勝敗表!$AZ$6:$BA$11,2,0),"6") | L5: =IFERROR(VLOOKUP(2,リーグ勝敗表!$AZ$6:$BA$11,2,0),"2")&"-"&IFERROR(VLOOKUP(4,リーグ勝敗表!$AZ$6:$BA$11,2,0),"4") | M5: =日程表１!M5 | N5: =日程表１!N5 | O5: =IFERROR(VLOOKUP(2,リーグ勝敗表!$AZ$6:$BA$11,2,0),"2") | P5: ー | Q5: =IFERROR(VLOOKUP(6,リーグ勝敗表!$AZ$6:$BA$11,2,0),"6") | R5: =IFERROR(VLOOKUP(3,リーグ勝敗表!$AZ$6:$BA$11,2,0),"3")&"-"&IFERROR(VLOOKUP(4,リーグ勝敗表!$AZ$6:$BA$11,2,0),"4") | S5: =日程表１!S6 | T5: =日程表１!T6 | V5: ー
A6: =日程表１!A6 | B6: =日程表１!B6 | D6: ー | G6: =日程表１!G6 | H6: =日程表１!H6 | I6: =IFERROR(VLOOKUP(2,リーグ勝敗表!$AZ$6:$BA$11,2,0),"2") | J6: ー | K6: =IFERROR(VLOOKUP(3,リーグ勝敗表!$AZ$6:$BA$11,2,0),"3") | L6: =IFERROR(VLOOKUP(1,リーグ勝敗表!$AZ$6:$BA$11,2,0),"1")&"-"&IFERROR(VLOOKUP(6,リーグ勝敗表!$AZ$6:$BA$11,2,0),"6") | M6: =日程表１!M6 | N6: =日程表１!N6 | P6: ー | S6: =日程表１!S7 | T6: =日程表１!T7 | V6: ー
A7: =日程表１!A7 | B7: =日程表１!B7 | D7: ー | G7: =日程表１!G7 | H7: =日程表１!H7 | I7: =IFERROR(VLOOKUP(4,リーグ勝敗表!$AZ$6:$BA$11,2,0),"4") | J7: ー | K7: =IFERROR(VLOOKUP(5,リーグ勝敗表!$AZ$6:$BA$11,2,0),"5") | L7: =IFERROR(VLOOKUP(2,リーグ勝敗表!$AZ$6:$BA$11,2,0),"2")&"-"&IFERROR(VLOOKUP(3,リーグ勝敗表!$AZ$6:$BA$11,2,0),"3") | M7: =日程表１!M7 | N7: =日程表１!N7 | P7: ー | S7: =日程表１!S8 | T7: =日程表１!T8 | V7: ー
A8: =日程表１!A8 | B8: =日程表１!B8 | D8: ー | G8: =日程表１!G8 | H8: =日程表１!H8 | J8: ー | M8: =日程表１!M8 | N8: =日程表１!N8 | P8: ー | S8: =日程表１!S9 | T8: =日程表１!T9 | V8: ー
A9: =日程表１!A9 | B9: =日程表１!B9 | D9: ー | G9: =日程表１!G9 | H9: =日程表１!H9 | J9: ー | M9: =日程表１!M9 | N9: =日程表１!N9 | P9: ー | S9: =日程表１!S10 | T9: =日程表１!T10 | V9: ー
A10: =日程表１!A10 | B10: =日程表１!B10 | D10: ー | G10: =日程表１!G10 | H10: =日程表１!H10 | J10: ー | M10: =日程表１!M10 | N10: =日程表１!N10 | P10: ー | S10: =日程表１!S11 | T10: =日程表１!T11 | V10: ー
A11: =日程表１!A11 | B11: =日程表１!B11 | D11: ー | G11: =日程表１!G11 | H11: =日程表１!H11 | J11: ー | M11: =日程表１!M11 | N11: =日程表１!N11 | P11: ー | S11: =日程表１!S12 | T11: =日程表１!T12 | V11: ー
A12: =日程表１!A12 | B12: =日程表１!B12 | D12: ー | G12: =日程表１!G12 | H12: =日程表１!H12 | I12: =IFERROR(VLOOKUP(1,リーグ勝敗表!$AZ$6:$BA$11,2,0),"1") | J12: ー | K12: =IFERROR(VLOOKUP(2,リーグ勝敗表!$AZ$6:$BA$11,2,0),"2") | L12: =IFERROR(VLOOKUP(4,リーグ勝敗表!$AZ$6:$BA$11,2,0),"4")&"-"&IFERROR(VLOOKUP(5,リーグ勝敗表!$AZ$6:$BA$11,2,0),"5") | M12: =日程表１!M12 | N12: =日程表１!N12 | P12: ー | S12: =日程表１!S13 | T12: =日程表１!T13 | V12: ー
A13: =日程表１!A13 | B13: =日程表１!B13 | D13: ー | G13: =日程表１!G13 | H13: =日程表１!H13 | I13: =IFERROR(VLOOKUP(3,リーグ勝敗表!$AZ$6:$BA$11,2,0),"3") | J13: ー | K13: =IFERROR(VLOOKUP(5,リーグ勝敗表!$AZ$6:$BA$11,2,0),"5") | L13: =IFERROR(VLOOKUP(1,リーグ勝敗表!$AZ$6:$BA$11,2,0),"1")&"-"&IFERROR(VLOOKUP(2,リーグ勝敗表!$AZ$6:$BA$11,2,0),"2") | M13: =日程表１!M13 | N13: =日程表１!N13 | P13: ー | S13: 10 | T13: 土 | V13: ー
A14: =日程表１!A14 | B14: =日程表１!B14 | D14: ー | G14: =日程表１!G14 | H14: =日程表１!H14 | I14: =IFERROR(VLOOKUP(4,リーグ勝敗表!$AZ$6:$BA$11,2,0),"4") | J14: ー | K14: =IFERROR(VLOOKUP(6,リーグ勝敗表!$AZ$6:$BA$11,2,0),"6") | L14: =IFERROR(VLOOKUP(3,リーグ勝敗表!$AZ$6:$BA$11,2,0),"3")&"-"&IFERROR(VLOOKUP(5,リーグ勝敗表!$AZ$6:$BA$11,2,0),"5") | M14: =日程表１!M14 | N14: =日程表１!N14 | P14: ー
A15: =日程表１!A15 | B15: =日程表１!B15 | D15: ー | G15: =日程表１!G15 | H15: =日程表１!H15 | J15: ー | M15: =日程表１!M15 | N15: =日程表１!N15 | P15: ー
A16: =日程表１!A16 | B16: =日程表１!B16 | D16: ー | G16: =日程表１!G16 | H16: =日程表１!H16 | J16: ー | M16: =日程表１!M16 | N16: =日程表１!N16 | P16: ー
A17: =日程表１!A17 | B17: =日程表１!B17 | D17: ー | G17: =日程表１!G17 | H17: =日程表１!H17 | J17: ー | M17: =日程表１!M17 | N17: =日程表１!N17 | P17: ー | S17: NO. | T17: team
A18: =日程表１!A18 | B18: =日程表１!B18 | D18: ー | G18: =日程表１!G18 | H18: =日程表１!H18 | J18: ー | M18: =日程表１!M18 | N18: =日程表１!N18 | P18: ー | S18: 1 | T18: =リーグ勝敗表!AX6
A19: =日程表１!A19 | B19: =日程表１!B19 | D19: ー | G19: =日程表１!G19 | H19: =日程表１!H19 | I19: 予備日 | M19: =日程表１!M19 | N19: =日程表１!N19 | P19: ー | S19: 2 | T19: =リーグ勝敗表!AX8
A20: =日程表１!A20 | B20: =日程表１!B20 | D20: ー | G20: =日程表１!G20 | H20: =日程表１!H20 | I20: 予備日 | M20: =日程表１!M20 | N20: =日程表１!N20 | P20: ー | S20: 3 | T20: =リーグ勝敗表!AX10
A21: =日程表１!A21 | B21: =日程表１!B21 | D21: ー | G21: =日程表１!G21 | H21: =日程表１!H21 | I21: 予備日 | M21: =日程表１!M21 | N21: =日程表１!N21 | P21: ー | S21: 4 | T21: =リーグ勝敗表!AX12
A22: =日程表１!A22 | B22: =日程表１!B22 | D22: ー | G22: =日程表１!G22 | H22: =日程表１!H22 | J22: ー | M22: =日程表１!M22 | N22: =日程表１!N22 | P22: ー | S22: 5 | T22: =リーグ勝敗表!AX14
A23: =日程表１!A23 | B23: =日程表１!B23 | D23: ー | G23: =日程表１!G23 | H23: =日程表１!H23 | J23: ー | M23: =日程表１!M23 | N23: =日程表１!N23 | P23: ー | S23: 6 | T23: =リーグ勝敗表!AX16
A24: =日程表１!A24 | B24: =日程表１!B24 | D24: ー | G24: =日程表１!G24 | H24: =日程表１!H24 | J24: ー | M24: =日程表１!M24 | N24: =日程表１!N24 | P24: ー | S24: 7 | T24: =リーグ勝敗表!AX18
A25: =日程表１!A25 | B25: =日程表１!B25 | D25: ー | G25: =日程表１!G25 | H25: =日程表１!H25 | J25: ー | M25: =日程表１!M25 | N25: =日程表１!N25 | P25: ー | S25: 8 | T25: =リーグ勝敗表!AX20
A26: =日程表１!A26 | B26: =日程表１!B26 | D26: ー | G26: =日程表１!G26 | H26: =日程表１!H26 | I26: =IFERROR(VLOOKUP(2,リーグ勝敗表!$AZ$6:$BA$11,2,0),"2") | J26: ー | K26: =IFERROR(VLOOKUP(5,リーグ勝敗表!$AZ$6:$BA$11,2,0),"5") | L26: =IFERROR(VLOOKUP(4,リーグ勝敗表!$AZ$6:$BA$11,2,0),"4")&"-"&IFERROR(VLOOKUP(6,リーグ勝敗表!$AZ$6:$BA$11,2,0),"6") | M26: =日程表１!M26 | N26: =日程表１!N26 | P26: ー | S26: 9 | T26: =リーグ勝敗表!AX22
A27: =日程表１!A27 | B27: =日程表１!B27 | D27: ー | G27: =日程表１!G27 | H27: =日程表１!H27 | I27: =IFERROR(VLOOKUP(1,リーグ勝敗表!$AZ$6:$BA$11,2,0),"1") | J27: ー | K27: =IFERROR(VLOOKUP(4,リーグ勝敗表!$AZ$6:$BA$11,2,0),"4") | L27: =IFERROR(VLOOKUP(2,リーグ勝敗表!$AZ$6:$BA$11,2,0),"2")&"-"&IFERROR(VLOOKUP(5,リーグ勝敗表!$AZ$6:$BA$11,2,0),"5") | M27: =日程表１!M27 | N27: =日程表１!N27 | P27: ー | S27: 10 | T27: =リーグ勝敗表!AX24
A28: =日程表１!A28 | B28: =日程表１!B28 | D28: ー | G28: =日程表１!G28 | H28: =日程表１!H28 | I28: =IFERROR(VLOOKUP(3,リーグ勝敗表!$AZ$6:$BA$11,2,0),"3") | J28: ー | K28: =IFERROR(VLOOKUP(6,リーグ勝敗表!$AZ$6:$BA$11,2,0),"6") | L28: =IFERROR(VLOOKUP(1,リーグ勝敗表!$AZ$6:$BA$11,2,0),"1")&"-"&IFERROR(VLOOKUP(4,リーグ勝敗表!$AZ$6:$BA$11,2,0),"4") | M28: =日程表１!M28 | N28: =日程表１!N28 | P28: ー | S28: 11 | T28: =リーグ勝敗表!AX26
A29: =日程表１!A29 | B29: =日程表１!B29 | C29: =IFERROR(VLOOKUP(1,リーグ勝敗表!$AZ$6:$BA$11,2,0),"1") | D29: ー | E29: =IFERROR(VLOOKUP(3,リーグ勝敗表!$AZ$6:$BA$11,2,0),"3") | F29: =IFERROR(VLOOKUP(2,リーグ勝敗表!$AZ$6:$BA$11,2,0),"2")&"-"&IFERROR(VLOOKUP(6,リーグ勝敗表!$AZ$6:$BA$11,2,0),"6") | G29: =日程表１!G29 | H29: =日程表１!H29 | J29: ー | M29: =日程表１!M29 | N29: =日程表１!N29 | P29: ー
A30: =日程表１!A30 | B30: =日程表１!B30 | C30: =IFERROR(VLOOKUP(5,リーグ勝敗表!$AZ$6:$BA$11,2,0),"5") | D30: ー | E30: =IFERROR(VLOOKUP(6,リーグ勝敗表!$AZ$6:$BA$11,2,0),"6") | F30: =IFERROR(VLOOKUP(1,リーグ勝敗表!$AZ$6:$BA$11,2,0),"1")&"-"&IFERROR(VLOOKUP(3,リーグ勝敗表!$AZ$6:$BA$11,2,0),"3") | G30: =日程表１!G30 | H30: =日程表１!H30 | J30: ー | M30: =日程表１!M30 | N30: =日程表１!N30 | P30: ー
A31: =日程表１!A31 | B31: =日程表１!B31 | C31: =IFERROR(VLOOKUP(2,リーグ勝敗表!$AZ$6:$BA$11,2,0),"2") | D31: ー | E31: =IFERROR(VLOOKUP(4,リーグ勝敗表!$AZ$6:$BA$11,2,0),"4") | F31: =IFERROR(VLOOKUP(5,リーグ勝敗表!$AZ$6:$BA$11,2,0),"5")&"-"&IFERROR(VLOOKUP(6,リーグ勝敗表!$AZ$6:$BA$11,2,0),"6") | G31: =日程表１!G31 | H31: =日程表１!H31 | J31: ー | M31: =日程表１!M31 | N31: =日程表１!N31 | P31: ー
A32: =日程表１!A32 | B32: =日程表１!B32 | D32: ー | G32: =日程表１!G32 | H32: =日程表１!H32 | J32: ー | M32: =日程表１!M32 | N32: =日程表１!N32 | P32: ー
A33: =日程表１!A33 | B33: =日程表１!B33 | D33: ー | G33: =日程表１!G33 | H33: =日程表１!H33 | I33: =IFERROR(VLOOKUP(1,リーグ勝敗表!$AZ$6:$BA$11,2,0),"1") | J33: ー | K33: =IFERROR(VLOOKUP(5,リーグ勝敗表!$AZ$6:$BA$11,2,0),"5") | L33: =IFERROR(VLOOKUP(3,リーグ勝敗表!$AZ$6:$BA$11,2,0),"3")&"-"&IFERROR(VLOOKUP(6,リーグ勝敗表!$AZ$6:$BA$11,2,0),"6") | M33: =日程表１!M33 | N33: =日程表１!N33 | P33: ー
A34: =日程表１!A34 | B34: =日程表１!B34 | D34: ー | J34: ー | M34: =日程表１!M34 | N34: =日程表１!N34 | P34: ー
